Workbook

Sheet Raw Prices
A1: Justin Haniff
C2: Date | D2: Hist. Price
D3: AT&T | E3: AMD | F3: ORCL | G3: S&P 500
C4: 45657 | D4: 22.77 | E4: 120.79 | F4: 166.64 | G4: 586.08
C5: 45656 | D5: 22.61 | E5: 122.44 | F5: 166.91 | G5: 588.22
C6: 45653 | D6: 22.86 | E6: 125.19 | F6: 168.96 | G6: 595.01
C7: 45652 | D7: 22.96 | E7: 125.06 | F7: 171.68 | G7: 601.34
C8: 45650 | D8: 22.95 | E8: 126.29 | F8: 171.41 | G8: 601.3
C9: 45649 | D9: 22.84 | E9: 124.6 | F9: 169.14 | G9: 594.69
C10: 45646 | D10: 22.75 | E10: 119.21 | F10: 169.66 | G10: 591.15
C11: 45645 | D11: 22.57 | E11: 118.88 | F11: 168.79 | G11: 586.1
C12: 45644 | D12: 22.48 | E12: 121.41 | F12: 165.41 | G12: 586.28
C13: 45643 | D13: 22.83 | E13: 125.02 | F13: 169.71 | G13: 604.29
C14: 45642 | D14: 22.84 | E14: 126.69 | F14: 171.23 | G14: 606.79
C15: 45639 | D15: 23.63 | E15: 126.91 | F15: 173.39 | G15: 604.21
... C505: 44929 | D505: 18.74 | E505: 64.02 | F505: 83.72 | G505: 380.82

Sheet Returns
B2: Date | C2: Returns | G2: French Rates
C3: AT&T | D3: AMD | E3: ORCL | F3: S&P 500 | G3: RF French | H3: RF/100
B4: 45657 | C4: =('Raw Prices'!D4-'Raw Prices'!D5)/'Raw Prices'!D5 -> 0.0070765148 | D4: =('Raw Prices'!E4-'Raw Prices'!E5)/'Raw Prices'!E5 -> -0.013475988 | E4: =('Raw Prices'!F4-'Raw Prices'!F5)/'Raw Prices'!F5 -> -0.0016176382 | F4: =('Raw Prices'!G4-'Raw Prices'!G5)/'Raw Prices'!G5 -> -0.0036380946 | G4: 0.02 | H4: =G4/100 -> 0.0002
B5: 45656 | C5: =('Raw Prices'!D5-'Raw Prices'!D6)/'Raw Prices'!D6 -> -0.010936133 | D5: =('Raw Prices'!E5-'Raw Prices'!E6)/'Raw Prices'!E6 -> -0.021966611 | E5: =('Raw Prices'!F5-'Raw Prices'!F6)/'Raw Prices'!F6 -> -0.012133049 | F5: =('Raw Prices'!G5-'Raw Prices'!G6)/'Raw Prices'!G6 -> -0.011411573 | G5: 0.02 | H5: =G5/100 -> 0.0002
B6: 45653 | C6: =('Raw Prices'!D6-'Raw Prices'!D7)/'Raw Prices'!D7 -> -0.0043554007 | D6: =('Raw Prices'!E6-'Raw Prices'!E7)/'Raw Prices'!E7 -> 0.001039501 | E6: =('Raw Prices'!F6-'Raw Prices'!F7)/'Raw Prices'!F7 -> -0.01584343 | F6: =('Raw Prices'!G6-'Raw Prices'!G7)/'Raw Prices'!G7 -> -0.010526491 | G6: 0.02 | H6: =G6/100 -> 0.0002
B7: 45652 | C7: =('Raw Prices'!D7-'Raw Prices'!D8)/'Raw Prices'!D8 -> 0.00043572985 | D7: =('Raw Prices'!E7-'Raw Prices'!E8)/'Raw Prices'!E8 -> -0.0097394885 | E7: =('Raw Prices'!F7-'Raw Prices'!F8)/'Raw Prices'!F8 -> 0.0015751706 | F7: =('Raw Prices'!G7-'Raw Prices'!G8)/'Raw Prices'!G8 -> 6.6522535e-05 | G7: 0.02 | H7: =G7/100 -> 0.0002
B8: 45650 | C8: =('Raw Prices'!D8-'Raw Prices'!D9)/'Raw Prices'!D9 -> 0.0048161121 | D8: =('Raw Prices'!E8-'Raw Prices'!E9)/'Raw Prices'!E9 -> 0.013563403 | E8: =('Raw Prices'!F8-'Raw Prices'!F9)/'Raw Prices'!F9 -> 0.013420835 | F8: =('Raw Prices'!G8-'Raw Prices'!G9)/'Raw Prices'!G9 -> 0.011115035 | G8: 0.02 | H8: =G8/100 -> 0.0002
B9: 45649 | C9: =('Raw Prices'!D9-'Raw Prices'!D10)/'Raw Prices'!D10 -> 0.003956044 | D9: =('Raw Prices'!E9-'Raw Prices'!E10)/'Raw Prices'!E10 -> 0.045214328 | E9: =('Raw Prices'!F9-'Raw Prices'!F10)/'Raw Prices'!F10 -> -0.0030649534 | F9: =('Raw Prices'!G9-'Raw Prices'!G10)/'Raw Prices'!G10 -> 0.0059883278 | G9: 0.02 | H9: =G9/100 -> 0.0002
B10: 45646 | C10: =('Raw Prices'!D10-'Raw Prices'!D11)/'Raw Prices'!D11 -> 0.0079751883 | D10: =('Raw Prices'!E10-'Raw Prices'!E11)/'Raw Prices'!E11 -> 0.0027759085 | E10: =('Raw Prices'!F10-'Raw Prices'!F11)/'Raw Prices'!F11 -> 0.0051543338 | F10: =('Raw Prices'!G10-'Raw Prices'!G11)/'Raw Prices'!G11 -> 0.0086162771 | G10: 0.02 | H10: =G10/100 -> 0.0002
B11: 45645 | C11: =('Raw Prices'!D11-'Raw Prices'!D12)/'Raw Prices'!D12 -> 0.0040035587 | D11: =('Raw Prices'!E11-'Raw Prices'!E12)/'Raw Prices'!E12 -> -0.020838481 | E11: =('Raw Prices'!F11-'Raw Prices'!F12)/'Raw Prices'!F12 -> 0.020434073 | F11: =('Raw Prices'!G11-'Raw Prices'!G12)/'Raw Prices'!G12 -> -0.00030702054 | G11: 0.02 | H11: =G11/100 -> 0.0002
B12: 45644 | C12: =('Raw Prices'!D12-'Raw Prices'!D13)/'Raw Prices'!D13 -> -0.015330705 | D12: =('Raw Prices'!E12-'Raw Prices'!E13)/'Raw Prices'!E13 -> -0.02887538 | E12: =('Raw Prices'!F12-'Raw Prices'!F13)/'Raw Prices'!F13 -> -0.02533734 | F12: =('Raw Prices'!G12-'Raw Prices'!G13)/'Raw Prices'!G13 -> -0.029803571 | G12: 0.02 | H12: =G12/100 -> 0.0002
B13: 45643 | C13: =('Raw Prices'!D13-'Raw Prices'!D14)/'Raw Prices'!D14 -> -0.00043782837 | D13: =('Raw Prices'!E13-'Raw Prices'!E14)/'Raw Prices'!E14 -> -0.013181782 | E13: =('Raw Prices'!F13-'Raw Prices'!F14)/'Raw Prices'!F14 -> -0.0088769491 | F13: =('Raw Prices'!G13-'Raw Prices'!G14)/'Raw Prices'!G14 -> -0.0041200415 | G13: 0.02 | H13: =G13/100 -> 0.0002
B14: 45642 | C14: =('Raw Prices'!D14-'Raw Prices'!D15)/'Raw Prices'!D15 -> -0.033432078 | D14: =('Raw Prices'!E14-'Raw Prices'!E15)/'Raw Prices'!E15 -> -0.0017335119 | E14: =('Raw Prices'!F14-'Raw Prices'!F15)/'Raw Prices'!F15 -> -0.012457466 | F14: =('Raw Prices'!G14-'Raw Prices'!G15)/'Raw Prices'!G15 -> 0.0042700386 | G14: 0.02 | H14: =G14/100 -> 0.0002
B15: 45639 | C15: =('Raw Prices'!D15-'Raw Prices'!D16)/'Raw Prices'!D16 -> 0.011558219 | D15: =('Raw Prices'!E15-'Raw Prices'!E16)/'Raw Prices'!E16 -> -0.028254211 | E15: =('Raw Prices'!F15-'Raw Prices'!F16)/'Raw Prices'!F16 -> -0.011008442 | F15: =('Raw Prices'!G15-'Raw Prices'!G16)/'Raw Prices'!G16 -> -0.00019856701 | G15: 0.02 | H15: =G15/100 -> 0.0002
... B504: 44930 | C504: =('Raw Prices'!D504-'Raw Prices'!D505)/'Raw Prices'!D505 -> 0.021344717 | D504: =('Raw Prices'!E504-'Raw Prices'!E505)/'Raw Prices'!E505 -> 0.009996876 | E504: =('Raw Prices'!F504-'Raw Prices'!F505)/'Raw Prices'!F505 -> 0.0090778786 | F504: =('Raw Prices'!G504-'Raw Prices'!G505)/'Raw Prices'!G505 -> 0.0077201828 | G504: 0.02 | H504: =G504/100 -> 0.0002

Sheet Regression
B1: AT&T | D1: AMD | F1: ORCL
B2: X | C2: Y-AT&T | D2: X | E2: Y-AMD | F2: X | G2: Y-ORCL | I2: CAPM-style regression of stock returns on market returns
B3: =Returns!F4-Returns!H4 -> -0.0038380946 | C3: =Returns!C4-Returns!H4 -> 0.0068765148 | D3: =Returns!F4-Returns!H4 -> -0.0038380946 | E3: =Returns!D4-Returns!H4 -> -0.013675988 | F3: =Returns!F4-Returns!H4 -> -0.0038380946 | G3: =Returns!E4-Returns!H4 -> -0.0018176382
B4: =Returns!F5-Returns!H5 -> -0.011611573 | C4: =Returns!C5-Returns!H5 -> -0.011136133 | D4: =Returns!F5-Returns!H5 -> -0.011611573 | E4: =Returns!D5-Returns!H5 -> -0.022166611 | F4: =Returns!F5-Returns!H5 -> -0.011611573 | G4: =Returns!E5-Returns!H5 -> -0.012333049 | J4: AT&T
B5: =Returns!F6-Returns!H6 -> -0.010726491 | C5: =Returns!C6-Returns!H6 -> -0.0045554007 | D5: =Returns!F6-Returns!H6 -> -0.010726491 | E5: =Returns!D6-Returns!H6 -> 0.00083950104 | F5: =Returns!F6-Returns!H6 -> -0.010726491 | G5: =Returns!E6-Returns!H6 -> -0.01604343
B6: =Returns!F7-Returns!H7 -> -0.00013347747 | C6: =Returns!C7-Returns!H7 -> 0.00023572985 | D6: =Returns!F7-Returns!H7 -> -0.00013347747 | E6: =Returns!D7-Returns!H7 -> -0.0099394885 | F6: =Returns!F7-Returns!H7 -> -0.00013347747 | G6: =Returns!E7-Returns!H7 -> 0.0013751706 | J6: Regression Statistics
B7: =Returns!F8-Returns!H8 -> 0.010915035 | C7: =Returns!C8-Returns!H8 -> 0.0046161121 | D7: =Returns!F8-Returns!H8 -> 0.010915035 | E7: =Returns!D8-Returns!H8 -> 0.013363403 | F7: =Returns!F8-Returns!H8 -> 0.010915035 | G7: =Returns!E8-Returns!H8 -> 0.013220835 | J7: Multiple R | K7: 0.092617267
B8: =Returns!F9-Returns!H9 -> 0.0057883278 | C8: =Returns!C9-Returns!H9 -> 0.003756044 | D8: =Returns!F9-Returns!H9 -> 0.0057883278 | E8: =Returns!D9-Returns!H9 -> 0.045014328 | F8: =Returns!F9-Returns!H9 -> 0.0057883278 | G8: =Returns!E9-Returns!H9 -> -0.0032649534 | J8: R Square | K8: 0.0085779581
B9: =Returns!F10-Returns!H10 -> 0.0084162771 | C9: =Returns!C10-Returns!H10 -> 0.0077751883 | D9: =Returns!F10-Returns!H10 -> 0.0084162771 | E9: =Returns!D10-Returns!H10 -> 0.0025759085 | F9: =Returns!F10-Returns!H10 -> 0.0084162771 | G9: =Returns!E10-Returns!H10 -> 0.0049543338 | J9: Adjusted R Square | K9: 0.0065911404
B10: =Returns!F11-Returns!H11 -> -0.00050702054 | C10: =Returns!C11-Returns!H11 -> 0.0038035587 | D10: =Returns!F11-Returns!H11 -> -0.00050702054 | E10: =Returns!D11-Returns!H11 -> -0.021038481 | F10: =Returns!F11-Returns!H11 -> -0.00050702054 | G10: =Returns!E11-Returns!H11 -> 0.020234073 | J10: Standard Error | K10: 0.015203512
B11: =Returns!F12-Returns!H12 -> -0.030003571 | C11: =Returns!C12-Returns!H12 -> -0.015530705 | D11: =Returns!F12-Returns!H12 -> -0.030003571 | E11: =Returns!D12-Returns!H12 -> -0.02907538 | F11: =Returns!F12-Returns!H12 -> -0.030003571 | G11: =Returns!E12-Returns!H12 -> -0.02553734 | J11: Observations | K11: 501
B12: =Returns!F13-Returns!H13 -> -0.0043200415 | C12: =Returns!C13-Returns!H13 -> -0.00063782837 | D12: =Returns!F13-Returns!H13 -> -0.0043200415 | E12: =Returns!D13-Returns!H13 -> -0.013381782 | F12: =Returns!F13-Returns!H13 -> -0.0043200415 | G12: =Returns!E13-Returns!H13 -> -0.0090769491
B13: =Returns!F14-Returns!H14 -> 0.0040700386 | C13: =Returns!C14-Returns!H14 -> -0.033632078 | D13: =Returns!F14-Returns!H14 -> 0.0040700386 | E13: =Returns!D14-Returns!H14 -> -0.0019335119 | F13: =Returns!F14-Returns!H14 -> 0.0040700386 | G13: =Returns!E14-Returns!H14 -> -0.012657466 | J13: ANOVA
B14: =Returns!F15-Returns!H15 -> -0.00039856701 | C14: =Returns!C15-Returns!H15 -> 0.011358219 | D14: =Returns!F15-Returns!H15 -> -0.00039856701 | E14: =Returns!D15-Returns!H15 -> -0.028454211 | F14: =Returns!F15-Returns!H15 -> -0.00039856701 | G14: =Returns!E15-Returns!H15 -> -0.011208442 | K14: df | L14: SS | M14: MS | N14: F | O14: Significance F
B15: =Returns!F16-Returns!H16 -> -0.0053526026 | C15: =Returns!C16-Returns!H16 -> -0.0053107325 | D15: =Returns!F16-Returns!H16 -> -0.0053526026 | E15: =Returns!D16-Returns!H16 -> 0.003257549 | F15: =Returns!F16-Returns!H16 -> -0.0053526026 | G15: =Returns!E16-Returns!H16 -> -0.018455124 | J15: Regression | K15: 1 | L15: 0.00099796141 | M15: 0.00099796141 | N15: 4.3174359 | O15: 0.038234419
B16: =Returns!F17-Returns!H17 -> 0.0075305906 | C16: =Returns!C17-Returns!H17 -> -0.0014760527 | D16: =Returns!F17-Returns!H17 -> 0.0075305906 | E16: =Returns!D17-Returns!H17 -> 0.018666447 | F16: =Returns!F17-Returns!H17 -> 0.0075305906 | G16: =Returns!E17-Returns!H17 -> 0.0045260043 | J16: Residual | K16: 499 | L16: 0.11534224 | M16: 0.00023114678
B17: =Returns!F18-Returns!H18 -> -0.0033090825 | C17: =Returns!C18-Returns!H18 -> 0.0057905862 | D17: =Returns!F18-Returns!H18 -> -0.0033090825 | E17: =Returns!D18-Returns!H18 -> -0.024116864 | F17: =Returns!F18-Returns!H18 -> -0.0033090825 | G17: =Returns!E18-Returns!H18 -> -0.066936676 | J17: Total | K17: 500 | L17: 0.11634021
B18: =Returns!F19-Returns!H19 -> -0.0053496356 | C18: =Returns!C19-Returns!H19 -> -0.021556784 | D18: =Returns!F19-Returns!H19 -> -0.0053496356 | E18: =Returns!D19-Returns!H19 -> -0.055903875 | F18: =Returns!F19-Returns!H19 -> -0.0053496356 | G18: =Returns!E19-Returns!H19 -> -0.0066687777
B19: =Returns!F20-Returns!H20 -> 0.0016956252 | C19: =Returns!C20-Returns!H20 -> 0.0018981956 | D19: =Returns!F20-Returns!H20 -> 0.0016956252 | E19: =Returns!D20-Returns!H20 -> -0.019795359 | F19: =Returns!F20-Returns!H20 -> 0.0016956252 | G19: =Returns!E20-Returns!H20 -> 0.029063316 | K19: Coefficients | L19: Standard Error | M19: t Stat | N19: P-value | O19: Lower 95% | P19: Upper 95% | Q19: Lower 95.0% | R19: Upper 95.0%
B20: =Returns!F21-Returns!H21 -> -0.0018456571 | C20: =Returns!C21-Returns!H21 -> 0.012549681 | D20: =Returns!F21-Returns!H21 -> -0.0018456571 | E20: =Returns!D21-Returns!H21 -> -0.018465157 | F20: =Returns!F21-Returns!H21 -> -0.0018456571 | G20: =Returns!E21-Returns!H21 -> -0.010561868 | J20: Intercept | K20: 0.00018447459 | L20: 0.00068172476 | M20: 0.2705998 | N20: 0.78681073 | O20: -0.0011549301 | P20: 0.0015238793 | Q20: -0.0011549301 | R20: 0.0015238793
B21: =Returns!F22-Returns!H22 -> 0.0060095345 | C21: =Returns!C22-Returns!H22 -> -0.0090458298 | D21: =Returns!F22-Returns!H22 -> 0.0060095345 | E21: =Returns!D22-Returns!H22 -> 0.013956924 | F21: =Returns!F22-Returns!H22 -> 0.0060095345 | G21: =Returns!E22-Returns!H22 -> 0.028779168 | J21: X | K21: 0.17405863 | L21: 0.083768863 | M21: 2.077844 | N21: 0.038234419 | O21: 0.0094754862 | P21: 0.33864178 | Q21: 0.0094754862 | R21: 0.33864178
B22: =Returns!F23-Returns!H23 -> 0.00026386031 | C22: =Returns!C23-Returns!H23 -> 0.045614978 | D22: =Returns!F23-Returns!H23 -> 0.00026386031 | E22: =Returns!D23-Returns!H23 -> -0.00076314233 | F22: =Returns!F23-Returns!H23 -> 0.00026386031 | G22: =Returns!E23-Returns!H23 -> 0.0079583154
B23: =Returns!F24-Returns!H24 -> 0.0015923824 | C23: =Returns!C24-Returns!H24 -> -0.020061831 | D23: =Returns!F24-Returns!H24 -> 0.0015923824 | E23: =Returns!D24-Returns!H24 -> 0.035411445 | F23: =Returns!F24-Returns!H24 -> 0.0015923824 | G23: =Returns!E24-Returns!H24 -> -0.018756589
B24: =Returns!F25-Returns!H25 -> 0.0060121136 | C24: =Returns!C25-Returns!H25 -> -0.0049271165 | D24: =Returns!F25-Returns!H25 -> 0.0060121136 | E24: =Returns!D25-Returns!H25 -> 0.006662889 | F24: =Returns!F25-Returns!H25 -> 0.0060121136 | G24: =Returns!E25-Returns!H25 -> 0.011513191 | J24: AMD
B25: =Returns!F26-Returns!H26 -> -0.0032300508 | C25: =Returns!C26-Returns!H26 -> 0.0075955825 | D25: =Returns!F26-Returns!H26 -> -0.0032300508 | E25: =Returns!D26-Returns!H26 -> -0.010946442 | F25: =Returns!F26-Returns!H26 -> -0.0032300508 | G25: =Returns!E26-Returns!H26 -> -0.040489962
B26: =Returns!F27-Returns!H27 -> 0.0050214952 | C26: =Returns!C27-Returns!H27 -> -0.00063290043 | D26: =Returns!F27-Returns!H27 -> 0.0050214952 | E26: =Returns!D27-Returns!H27 -> -0.02436212 | F26: =Returns!F27-Returns!H27 -> 0.0050214952 | G26: =Returns!E27-Returns!H27 -> 0.012460248 | J26: Regression Statistics
B27: =Returns!F28-Returns!H28 -> 0.0031920505 | C27: =Returns!C28-Returns!H28 -> -0.0036512511 | D27: =Returns!F28-Returns!H28 -> 0.0031920505 | E27: =Returns!D28-Returns!H28 -> 0.019893965 | F27: =Returns!F28-Returns!H28 -> 0.0031920505 | G27: =Returns!E28-Returns!H28 -> -0.022562057 | J27: Multiple R | K27: 0.55528849
B28: =Returns!F29-Returns!H29 -> 0.002899365 | C28: =Returns!C29-Returns!H29 -> 0.0085032202 | D28: =Returns!F29-Returns!H29 -> 0.002899365 | E28: =Returns!D29-Returns!H29 -> 0.0060550004 | F28: =Returns!F29-Returns!H29 -> 0.002899365 | G28: =Returns!E29-Returns!H29 -> -0.00092753729 | J28: R Square | K28: 0.30834531
B29: =Returns!F30-Returns!H30 -> 0.0051683319 | C29: =Returns!C30-Returns!H30 -> 0.0063703022 | D29: =Returns!F30-Returns!H30 -> 0.0051683319 | E29: =Returns!D30-Returns!H30 -> -0.0009994186 | F29: =Returns!F30-Returns!H30 -> 0.0051683319 | G29: =Returns!E30-Returns!H30 -> 0.0086073394 | J29: Adjusted R Square | K29: 0.30695922
B30: =Returns!F31-Returns!H31 -> 0.00013881077 | C30: =Returns!C31-Returns!H31 -> 0.0041994721 | D30: =Returns!F31-Returns!H31 -> 0.00013881077 | E30: =Returns!D31-Returns!H31 -> -0.013041667 | F30: =Returns!F31-Returns!H31 -> 0.00013881077 | G30: =Returns!E31-Returns!H31 -> 0.0095935416 | J30: Standard Error | K30: 0.02489961
B31: =Returns!F32-Returns!H32 -> 0.0034555301 | C31: =Returns!C32-Returns!H32 -> -0.011509265 | D31: =Returns!F32-Returns!H32 -> 0.0034555301 | E31: =Returns!D32-Returns!H32 -> 0.0031110199 | F31: =Returns!F32-Returns!H32 -> 0.0034555301 | G31: =Returns!E32-Returns!H32 -> 0.016867787 | J31: Observations | K31: 501
B32: =Returns!F33-Returns!H33 -> 0.0038973111 | C32: =Returns!C33-Returns!H33 -> 0.01346843 | D32: =Returns!F33-Returns!H33 -> 0.0038973111 | E32: =Returns!D33-Returns!H33 -> 0.029673981 | F32: =Returns!F33-Returns!H33 -> 0.0038973111 | G32: =Returns!E33-Returns!H33 -> 0.010630521
B33: =Returns!F34-Returns!H34 -> -0.013008629 | C33: =Returns!C34-Returns!H34 -> 0.019125843 | D33: =Returns!F34-Returns!H34 -> -0.013008629 | E33: =Returns!D34-Returns!H34 -> -0.028577989 | F33: =Returns!F34-Returns!H34 -> -0.013008629 | G33: =Returns!E34-Returns!H34 -> -0.017895803 | J33: ANOVA
B34: =Returns!F35-Returns!H35 -> -0.0066301144 | C34: =Returns!C35-Returns!H35 -> -0.0024421525 | D34: =Returns!F35-Returns!H35 -> -0.0066301144 | E34: =Returns!D35-Returns!H35 -> -0.0035022254 | F34: =Returns!F35-Returns!H35 -> -0.0066301144 | G34: =Returns!E35-Returns!H35 -> -0.013805442 | K34: df | L34: SS | M34: MS | N34: F | O34: Significance F
B35: =Returns!F36-Returns!H36 -> 0.00028584352 | C35: =Returns!C36-Returns!H36 -> 0.006572009 | D35: =Returns!F36-Returns!H36 -> 0.00028584352 | E35: =Returns!D36-Returns!H36 -> -0.030346905 | F35: =Returns!F36-Returns!H36 -> 0.00028584352 | G35: =Returns!E36-Returns!H36 -> 6.3740901e-05 | J35: Regression | K35: 1 | L35: 0.13792204 | M35: 0.13792204 | N35: 222.45827 | O35: 7.2213411e-42
B36: =Returns!F37-Returns!H37 -> -0.0033064199 | C36: =Returns!C37-Returns!H37 -> -0.0073716719 | D36: =Returns!F37-Returns!H37 -> -0.0033064199 | E36: =Returns!D37-Returns!H37 -> -0.025446013 | F36: =Returns!F37-Returns!H37 -> -0.0033064199 | G36: =Returns!E37-Returns!H37 -> 0.0021793158 | J36: Residual | K36: 499 | L36: 0.30937531 | M36: 0.00061999059
B37: =Returns!F38-Returns!H38 -> 0.0007528745 | C37: =Returns!C38-Returns!H38 -> -0.0015428827 | D37: =Returns!F38-Returns!H38 -> 0.0007528745 | E37: =Returns!D38-Returns!H38 -> -0.0042554241 | F37: =Returns!F38-Returns!H38 -> 0.0007528745 | G37: =Returns!E38-Returns!H38 -> -0.0008340819 | J37: Total | K37: 500 | L37: 0.44729734
B38: =Returns!F39-Returns!H39 -> 0.0041316936 | C38: =Returns!C39-Returns!H39 -> 0.013411615 | D38: =Returns!F39-Returns!H39 -> 0.0041316936 | E38: =Returns!D39-Returns!H39 -> -0.012681645 | F38: =Returns!F39-Returns!H39 -> 0.0041316936 | G38: =Returns!E39-Returns!H39 -> 0.015253131
B39: =Returns!F40-Returns!H40 -> 0.0075321332 | C39: =Returns!C40-Returns!H40 -> -0.012744803 | D39: =Returns!F40-Returns!H40 -> 0.0075321332 | E39: =Returns!D40-Returns!H40 -> 0.03232929 | F39: =Returns!F40-Returns!H40 -> 0.0075321332 | G39: =Returns!E40-Returns!H40 -> 0.02810501 | K39: Coefficients | L39: Standard Error | M39: t Stat | N39: P-value | O39: Lower 95% | P39: Upper 95% | Q39: Lower 95.0% | R39: Upper 95.0%
B40: =Returns!F41-Returns!H41 -> 0.024665615 | C40: =Returns!C41-Returns!H41 -> 0.012044898 | D40: =Returns!F41-Returns!H41 -> 0.024665615 | E40: =Returns!D41-Returns!H41 -> 0.024083496 | F40: =Returns!F41-Returns!H41 -> 0.024665615 | G40: =Returns!E41-Returns!H41 -> 0.054870439 | J40: Intercept | K40: 9.3293505e-05 | L40: 0.0011164973 | M40: 0.083559093 | N40: 0.9334405 | O40: -0.0021003216 | P40: 0.0022869087 | Q40: -0.0021003216 | R40: 0.0022869087
...

Sheet SUMMARY
A1: The regression results indicate that each stock’s returns are positively related to market returns, with differing sensitivities that reflect varying levels of market exposure and risk relative to the S&P 500.
